[2024-06-16T02:34:20.086+0000] {taskinstance.py:1083} INFO - Dependencies all met for <TaskInstance: process_data_dag.process_data manual__2024-06-16T02:33:53.001239+00:00 [queued]>
[2024-06-16T02:34:20.091+0000] {taskinstance.py:1083} INFO - Dependencies all met for <TaskInstance: process_data_dag.process_data manual__2024-06-16T02:33:53.001239+00:00 [queued]>
[2024-06-16T02:34:20.092+0000] {taskinstance.py:1279} INFO - 
--------------------------------------------------------------------------------
[2024-06-16T02:34:20.092+0000] {taskinstance.py:1280} INFO - Starting attempt 1 of 2
[2024-06-16T02:34:20.092+0000] {taskinstance.py:1281} INFO - 
--------------------------------------------------------------------------------
[2024-06-16T02:34:20.102+0000] {taskinstance.py:1300} INFO - Executing <Task(PythonOperator): process_data> on 2024-06-16 02:33:53.001239+00:00
[2024-06-16T02:34:20.109+0000] {standard_task_runner.py:55} INFO - Started process 4240 to run task
[2024-06-16T02:34:20.111+0000] {standard_task_runner.py:82} INFO - Running: ['***', 'tasks', 'run', 'process_data_dag', 'process_data', 'manual__2024-06-16T02:33:53.001239+00:00', '--job-id', '32380', '--raw', '--subdir', 'DAGS_FOLDER/process_data.py', '--cfg-path', '/tmp/tmphl12p9_c']
[2024-06-16T02:34:20.111+0000] {standard_task_runner.py:83} INFO - Job 32380: Subtask process_data
[2024-06-16T02:34:20.153+0000] {task_command.py:388} INFO - Running <TaskInstance: process_data_dag.process_data manual__2024-06-16T02:33:53.001239+00:00 [running]> on host d460cb06525f
[2024-06-16T02:34:20.203+0000] {taskinstance.py:1509} INFO - Exporting the following env vars:
AIRFLOW_CTX_DAG_OWNER=***
AIRFLOW_CTX_DAG_ID=process_data_dag
AIRFLOW_CTX_TASK_ID=process_data
AIRFLOW_CTX_EXECUTION_DATE=2024-06-16T02:33:53.001239+00:00
AIRFLOW_CTX_TRY_NUMBER=1
AIRFLOW_CTX_DAG_RUN_ID=manual__2024-06-16T02:33:53.001239+00:00
[2024-06-16T02:34:20.232+0000] {taskinstance.py:1768} ERROR - Task failed with exception
Traceback (most recent call last):
  File "/home/airflow/.local/lib/python3.7/site-packages/airflow/operators/python.py", line 175, in execute
    return_value = self.execute_callable()
  File "/home/airflow/.local/lib/python3.7/site-packages/airflow/operators/python.py", line 192, in execute_callable
    return self.python_callable(*self.op_args, **self.op_kwargs)
  File "/opt/airflow/dags/process_data.py", line 164, in process_data
    save_dataframe(dataframe_weather, dest_weather)
  File "/opt/airflow/dags/process_data.py", line 150, in save_dataframe
    dataframe.to_json(path)
  File "/home/airflow/.local/lib/python3.7/site-packages/pandas/core/generic.py", line 2571, in to_json
    storage_options=storage_options,
  File "/home/airflow/.local/lib/python3.7/site-packages/pandas/io/json/_json.py", line 131, in to_json
    path_or_buf, "w", compression=compression, storage_options=storage_options
  File "/home/airflow/.local/lib/python3.7/site-packages/pandas/io/common.py", line 707, in get_handle
    newline="",
FileNotFoundError: [Errno 2] No such file or directory: 'dags/to/model_data/clean_data/weather.json'
[2024-06-16T02:34:20.240+0000] {taskinstance.py:1323} INFO - Marking task as UP_FOR_RETRY. dag_id=process_data_dag, task_id=process_data, execution_date=20240616T023353, start_date=20240616T023420, end_date=20240616T023420
[2024-06-16T02:34:20.247+0000] {standard_task_runner.py:105} ERROR - Failed to execute job 32380 for task process_data ([Errno 2] No such file or directory: 'dags/to/model_data/clean_data/weather.json'; 4240)
[2024-06-16T02:34:20.282+0000] {local_task_job.py:208} INFO - Task exited with return code 1
[2024-06-16T02:34:20.301+0000] {taskinstance.py:2578} INFO - 0 downstream tasks scheduled from follow-on schedule check
