[2024-06-16T01:48:03.622+0000] {taskinstance.py:1083} INFO - Dependencies all met for <TaskInstance: process_data_dag.fetch_and_save_data scheduled__2023-01-02T00:00:00+00:00 [queued]>
[2024-06-16T01:48:03.634+0000] {taskinstance.py:1083} INFO - Dependencies all met for <TaskInstance: process_data_dag.fetch_and_save_data scheduled__2023-01-02T00:00:00+00:00 [queued]>
[2024-06-16T01:48:03.634+0000] {taskinstance.py:1279} INFO - 
--------------------------------------------------------------------------------
[2024-06-16T01:48:03.634+0000] {taskinstance.py:1280} INFO - Starting attempt 1 of 2
[2024-06-16T01:48:03.634+0000] {taskinstance.py:1281} INFO - 
--------------------------------------------------------------------------------
[2024-06-16T01:48:03.656+0000] {taskinstance.py:1300} INFO - Executing <Task(PythonOperator): fetch_and_save_data> on 2023-01-02 00:00:00+00:00
[2024-06-16T01:48:03.668+0000] {standard_task_runner.py:55} INFO - Started process 242 to run task
[2024-06-16T01:48:03.671+0000] {standard_task_runner.py:82} INFO - Running: ['***', 'tasks', 'run', 'process_data_dag', 'fetch_and_save_data', 'scheduled__2023-01-02T00:00:00+00:00', '--job-id', '32055', '--raw', '--subdir', 'DAGS_FOLDER/process_data.py', '--cfg-path', '/tmp/tmpozxbb95v']
[2024-06-16T01:48:03.671+0000] {standard_task_runner.py:83} INFO - Job 32055: Subtask fetch_and_save_data
[2024-06-16T01:48:03.759+0000] {task_command.py:388} INFO - Running <TaskInstance: process_data_dag.fetch_and_save_data scheduled__2023-01-02T00:00:00+00:00 [running]> on host 74f2b0340b57
[2024-06-16T01:48:03.895+0000] {taskinstance.py:1509} INFO - Exporting the following env vars:
AIRFLOW_CTX_DAG_OWNER=***
AIRFLOW_CTX_DAG_ID=process_data_dag
AIRFLOW_CTX_TASK_ID=fetch_and_save_data
AIRFLOW_CTX_EXECUTION_DATE=2023-01-02T00:00:00+00:00
AIRFLOW_CTX_TRY_NUMBER=1
AIRFLOW_CTX_DAG_RUN_ID=scheduled__2023-01-02T00:00:00+00:00
[2024-06-16T01:48:03.898+0000] {taskinstance.py:1768} ERROR - Task failed with exception
Traceback (most recent call last):
  File "/home/airflow/.local/lib/python3.7/site-packages/airflow/operators/python.py", line 175, in execute
    return_value = self.execute_callable()
  File "/home/airflow/.local/lib/python3.7/site-packages/airflow/operators/python.py", line 192, in execute_callable
    return self.python_callable(*self.op_args, **self.op_kwargs)
  File "/opt/airflow/dags/process_data.py", line 34, in fetch_and_save_data
    config = import_config()
  File "/opt/airflow/dags/process_data.py", line 17, in import_config
    with open('/home/evandro/Área de trabalho/case/case_zebrinha-azul/config/config.yaml', 'r') as config:
FileNotFoundError: [Errno 2] No such file or directory: '/home/evandro/Área de trabalho/case/case_zebrinha-azul/config/config.yaml'
[2024-06-16T01:48:03.908+0000] {taskinstance.py:1323} INFO - Marking task as UP_FOR_RETRY. dag_id=process_data_dag, task_id=fetch_and_save_data, execution_date=20230102T000000, start_date=20240616T014803, end_date=20240616T014803
[2024-06-16T01:48:03.960+0000] {standard_task_runner.py:105} ERROR - Failed to execute job 32055 for task fetch_and_save_data ([Errno 2] No such file or directory: '/home/evandro/Área de trabalho/case/case_zebrinha-azul/config/config.yaml'; 242)
[2024-06-16T01:48:04.006+0000] {local_task_job.py:208} INFO - Task exited with return code 1
[2024-06-16T01:48:04.064+0000] {taskinstance.py:2578} INFO - 0 downstream tasks scheduled from follow-on schedule check
[2024-06-16T01:50:17.831+0000] {taskinstance.py:1083} INFO - Dependencies all met for <TaskInstance: process_data_dag.fetch_and_save_data scheduled__2023-01-02T00:00:00+00:00 [queued]>
[2024-06-16T01:50:17.841+0000] {taskinstance.py:1083} INFO - Dependencies all met for <TaskInstance: process_data_dag.fetch_and_save_data scheduled__2023-01-02T00:00:00+00:00 [queued]>
[2024-06-16T01:50:17.841+0000] {taskinstance.py:1279} INFO - 
--------------------------------------------------------------------------------
[2024-06-16T01:50:17.842+0000] {taskinstance.py:1280} INFO - Starting attempt 1 of 2
[2024-06-16T01:50:17.842+0000] {taskinstance.py:1281} INFO - 
--------------------------------------------------------------------------------
[2024-06-16T01:50:17.860+0000] {taskinstance.py:1300} INFO - Executing <Task(PythonOperator): fetch_and_save_data> on 2023-01-02 00:00:00+00:00
[2024-06-16T01:50:17.871+0000] {standard_task_runner.py:55} INFO - Started process 595 to run task
[2024-06-16T01:50:17.874+0000] {standard_task_runner.py:82} INFO - Running: ['***', 'tasks', 'run', 'process_data_dag', 'fetch_and_save_data', 'scheduled__2023-01-02T00:00:00+00:00', '--job-id', '32081', '--raw', '--subdir', 'DAGS_FOLDER/process_data.py', '--cfg-path', '/tmp/tmpo1bkeul0']
[2024-06-16T01:50:17.875+0000] {standard_task_runner.py:83} INFO - Job 32081: Subtask fetch_and_save_data
[2024-06-16T01:50:17.947+0000] {task_command.py:388} INFO - Running <TaskInstance: process_data_dag.fetch_and_save_data scheduled__2023-01-02T00:00:00+00:00 [running]> on host 74f2b0340b57
[2024-06-16T01:50:18.036+0000] {taskinstance.py:1509} INFO - Exporting the following env vars:
AIRFLOW_CTX_DAG_OWNER=***
AIRFLOW_CTX_DAG_ID=process_data_dag
AIRFLOW_CTX_TASK_ID=fetch_and_save_data
AIRFLOW_CTX_EXECUTION_DATE=2023-01-02T00:00:00+00:00
AIRFLOW_CTX_TRY_NUMBER=1
AIRFLOW_CTX_DAG_RUN_ID=scheduled__2023-01-02T00:00:00+00:00
[2024-06-16T01:50:18.038+0000] {taskinstance.py:1768} ERROR - Task failed with exception
Traceback (most recent call last):
  File "/home/airflow/.local/lib/python3.7/site-packages/airflow/operators/python.py", line 175, in execute
    return_value = self.execute_callable()
  File "/home/airflow/.local/lib/python3.7/site-packages/airflow/operators/python.py", line 192, in execute_callable
    return self.python_callable(*self.op_args, **self.op_kwargs)
  File "/opt/airflow/dags/process_data.py", line 34, in fetch_and_save_data
    config = import_config()
  File "/opt/airflow/dags/process_data.py", line 17, in import_config
    with open('home/evandro/Área de trabalho/case/case_zebrinha-azul/config/config.yaml', 'r') as config:
FileNotFoundError: [Errno 2] No such file or directory: 'home/evandro/Área de trabalho/case/case_zebrinha-azul/config/config.yaml'
[2024-06-16T01:50:18.046+0000] {taskinstance.py:1323} INFO - Marking task as UP_FOR_RETRY. dag_id=process_data_dag, task_id=fetch_and_save_data, execution_date=20230102T000000, start_date=20240616T015017, end_date=20240616T015018
[2024-06-16T01:50:18.061+0000] {standard_task_runner.py:105} ERROR - Failed to execute job 32081 for task fetch_and_save_data ([Errno 2] No such file or directory: 'home/evandro/Área de trabalho/case/case_zebrinha-azul/config/config.yaml'; 595)
[2024-06-16T01:50:18.085+0000] {local_task_job.py:208} INFO - Task exited with return code 1
[2024-06-16T01:50:18.118+0000] {taskinstance.py:2578} INFO - 0 downstream tasks scheduled from follow-on schedule check
[2024-06-16T01:52:26.940+0000] {taskinstance.py:1083} INFO - Dependencies all met for <TaskInstance: process_data_dag.fetch_and_save_data scheduled__2023-01-02T00:00:00+00:00 [queued]>
[2024-06-16T01:52:26.948+0000] {taskinstance.py:1083} INFO - Dependencies all met for <TaskInstance: process_data_dag.fetch_and_save_data scheduled__2023-01-02T00:00:00+00:00 [queued]>
[2024-06-16T01:52:26.949+0000] {taskinstance.py:1279} INFO - 
--------------------------------------------------------------------------------
[2024-06-16T01:52:26.949+0000] {taskinstance.py:1280} INFO - Starting attempt 1 of 2
[2024-06-16T01:52:26.949+0000] {taskinstance.py:1281} INFO - 
--------------------------------------------------------------------------------
[2024-06-16T01:52:27.009+0000] {taskinstance.py:1300} INFO - Executing <Task(PythonOperator): fetch_and_save_data> on 2023-01-02 00:00:00+00:00
[2024-06-16T01:52:27.017+0000] {standard_task_runner.py:55} INFO - Started process 932 to run task
[2024-06-16T01:52:27.020+0000] {standard_task_runner.py:82} INFO - Running: ['***', 'tasks', 'run', 'process_data_dag', 'fetch_and_save_data', 'scheduled__2023-01-02T00:00:00+00:00', '--job-id', '32108', '--raw', '--subdir', 'DAGS_FOLDER/process_data.py', '--cfg-path', '/tmp/tmpste6t388']
[2024-06-16T01:52:27.020+0000] {standard_task_runner.py:83} INFO - Job 32108: Subtask fetch_and_save_data
[2024-06-16T01:52:27.084+0000] {task_command.py:388} INFO - Running <TaskInstance: process_data_dag.fetch_and_save_data scheduled__2023-01-02T00:00:00+00:00 [running]> on host 74f2b0340b57
[2024-06-16T01:52:27.161+0000] {taskinstance.py:1509} INFO - Exporting the following env vars:
AIRFLOW_CTX_DAG_OWNER=***
AIRFLOW_CTX_DAG_ID=process_data_dag
AIRFLOW_CTX_TASK_ID=fetch_and_save_data
AIRFLOW_CTX_EXECUTION_DATE=2023-01-02T00:00:00+00:00
AIRFLOW_CTX_TRY_NUMBER=1
AIRFLOW_CTX_DAG_RUN_ID=scheduled__2023-01-02T00:00:00+00:00
[2024-06-16T01:52:27.164+0000] {logging_mixin.py:137} INFO - /opt/***
[2024-06-16T01:52:27.164+0000] {taskinstance.py:1768} ERROR - Task failed with exception
Traceback (most recent call last):
  File "/home/airflow/.local/lib/python3.7/site-packages/airflow/operators/python.py", line 175, in execute
    return_value = self.execute_callable()
  File "/home/airflow/.local/lib/python3.7/site-packages/airflow/operators/python.py", line 192, in execute_callable
    return self.python_callable(*self.op_args, **self.op_kwargs)
  File "/opt/airflow/dags/process_data.py", line 35, in fetch_and_save_data
    config = import_config()
  File "/opt/airflow/dags/process_data.py", line 18, in import_config
    with open('home/evandro/Área de trabalho/case/case_zebrinha-azul/config/config.yaml', 'r') as config:
FileNotFoundError: [Errno 2] No such file or directory: 'home/evandro/Área de trabalho/case/case_zebrinha-azul/config/config.yaml'
[2024-06-16T01:52:27.171+0000] {taskinstance.py:1323} INFO - Marking task as UP_FOR_RETRY. dag_id=process_data_dag, task_id=fetch_and_save_data, execution_date=20230102T000000, start_date=20240616T015226, end_date=20240616T015227
[2024-06-16T01:52:27.185+0000] {standard_task_runner.py:105} ERROR - Failed to execute job 32108 for task fetch_and_save_data ([Errno 2] No such file or directory: 'home/evandro/Área de trabalho/case/case_zebrinha-azul/config/config.yaml'; 932)
[2024-06-16T01:52:27.232+0000] {local_task_job.py:208} INFO - Task exited with return code 1
[2024-06-16T01:52:27.264+0000] {taskinstance.py:2578} INFO - 0 downstream tasks scheduled from follow-on schedule check
[2024-06-16T01:54:48.603+0000] {taskinstance.py:1083} INFO - Dependencies all met for <TaskInstance: process_data_dag.fetch_and_save_data scheduled__2023-01-02T00:00:00+00:00 [queued]>
[2024-06-16T01:54:48.614+0000] {taskinstance.py:1083} INFO - Dependencies all met for <TaskInstance: process_data_dag.fetch_and_save_data scheduled__2023-01-02T00:00:00+00:00 [queued]>
[2024-06-16T01:54:48.614+0000] {taskinstance.py:1279} INFO - 
--------------------------------------------------------------------------------
[2024-06-16T01:54:48.614+0000] {taskinstance.py:1280} INFO - Starting attempt 1 of 2
[2024-06-16T01:54:48.614+0000] {taskinstance.py:1281} INFO - 
--------------------------------------------------------------------------------
[2024-06-16T01:54:48.629+0000] {taskinstance.py:1300} INFO - Executing <Task(PythonOperator): fetch_and_save_data> on 2023-01-02 00:00:00+00:00
[2024-06-16T01:54:48.638+0000] {standard_task_runner.py:55} INFO - Started process 1309 to run task
[2024-06-16T01:54:48.642+0000] {standard_task_runner.py:82} INFO - Running: ['***', 'tasks', 'run', 'process_data_dag', 'fetch_and_save_data', 'scheduled__2023-01-02T00:00:00+00:00', '--job-id', '32134', '--raw', '--subdir', 'DAGS_FOLDER/process_data.py', '--cfg-path', '/tmp/tmp8zbu8ad4']
[2024-06-16T01:54:48.642+0000] {standard_task_runner.py:83} INFO - Job 32134: Subtask fetch_and_save_data
[2024-06-16T01:54:48.712+0000] {task_command.py:388} INFO - Running <TaskInstance: process_data_dag.fetch_and_save_data scheduled__2023-01-02T00:00:00+00:00 [running]> on host 74f2b0340b57
[2024-06-16T01:54:48.790+0000] {taskinstance.py:1509} INFO - Exporting the following env vars:
AIRFLOW_CTX_DAG_OWNER=***
AIRFLOW_CTX_DAG_ID=process_data_dag
AIRFLOW_CTX_TASK_ID=fetch_and_save_data
AIRFLOW_CTX_EXECUTION_DATE=2023-01-02T00:00:00+00:00
AIRFLOW_CTX_TRY_NUMBER=1
AIRFLOW_CTX_DAG_RUN_ID=scheduled__2023-01-02T00:00:00+00:00
[2024-06-16T01:54:48.792+0000] {logging_mixin.py:137} INFO - /opt/***
[2024-06-16T01:54:48.793+0000] {taskinstance.py:1768} ERROR - Task failed with exception
Traceback (most recent call last):
  File "/home/airflow/.local/lib/python3.7/site-packages/airflow/operators/python.py", line 175, in execute
    return_value = self.execute_callable()
  File "/home/airflow/.local/lib/python3.7/site-packages/airflow/operators/python.py", line 192, in execute_callable
    return self.python_callable(*self.op_args, **self.op_kwargs)
  File "/opt/airflow/dags/process_data.py", line 35, in fetch_and_save_data
    config = import_config()
  File "/opt/airflow/dags/process_data.py", line 18, in import_config
    with open('config/config.yaml', 'r') as config:
FileNotFoundError: [Errno 2] No such file or directory: 'config/config.yaml'
[2024-06-16T01:54:48.800+0000] {taskinstance.py:1323} INFO - Marking task as UP_FOR_RETRY. dag_id=process_data_dag, task_id=fetch_and_save_data, execution_date=20230102T000000, start_date=20240616T015448, end_date=20240616T015448
[2024-06-16T01:54:48.812+0000] {standard_task_runner.py:105} ERROR - Failed to execute job 32134 for task fetch_and_save_data ([Errno 2] No such file or directory: 'config/config.yaml'; 1309)
[2024-06-16T01:54:48.853+0000] {local_task_job.py:208} INFO - Task exited with return code 1
[2024-06-16T01:54:48.886+0000] {taskinstance.py:2578} INFO - 0 downstream tasks scheduled from follow-on schedule check
