[2024-06-16T13:59:29.112+0000] {taskinstance.py:1083} INFO - Dependencies all met for <TaskInstance: process_data_dag.fetch_and_save_data manual__2024-06-16T13:59:18+00:00 [queued]>
[2024-06-16T13:59:29.118+0000] {taskinstance.py:1083} INFO - Dependencies all met for <TaskInstance: process_data_dag.fetch_and_save_data manual__2024-06-16T13:59:18+00:00 [queued]>
[2024-06-16T13:59:29.118+0000] {taskinstance.py:1279} INFO - 
--------------------------------------------------------------------------------
[2024-06-16T13:59:29.118+0000] {taskinstance.py:1280} INFO - Starting attempt 1 of 2
[2024-06-16T13:59:29.118+0000] {taskinstance.py:1281} INFO - 
--------------------------------------------------------------------------------
[2024-06-16T13:59:29.128+0000] {taskinstance.py:1300} INFO - Executing <Task(PythonOperator): fetch_and_save_data> on 2024-06-16 13:59:18+00:00
[2024-06-16T13:59:29.135+0000] {standard_task_runner.py:55} INFO - Started process 1049 to run task
[2024-06-16T13:59:29.138+0000] {standard_task_runner.py:82} INFO - Running: ['***', 'tasks', 'run', 'process_data_dag', 'fetch_and_save_data', 'manual__2024-06-16T13:59:18+00:00', '--job-id', '33237', '--raw', '--subdir', 'DAGS_FOLDER/process_data.py', '--cfg-path', '/tmp/tmp9z3pqm88']
[2024-06-16T13:59:29.138+0000] {standard_task_runner.py:83} INFO - Job 33237: Subtask fetch_and_save_data
[2024-06-16T13:59:29.181+0000] {task_command.py:388} INFO - Running <TaskInstance: process_data_dag.fetch_and_save_data manual__2024-06-16T13:59:18+00:00 [running]> on host 01364b699017
[2024-06-16T13:59:29.242+0000] {taskinstance.py:1509} INFO - Exporting the following env vars:
AIRFLOW_CTX_DAG_OWNER=***
AIRFLOW_CTX_DAG_ID=process_data_dag
AIRFLOW_CTX_TASK_ID=fetch_and_save_data
AIRFLOW_CTX_EXECUTION_DATE=2024-06-16T13:59:18+00:00
AIRFLOW_CTX_TRY_NUMBER=1
AIRFLOW_CTX_DAG_RUN_ID=manual__2024-06-16T13:59:18+00:00
[2024-06-16T14:00:54.602+0000] {taskinstance.py:1768} ERROR - Task failed with exception
Traceback (most recent call last):
  File "/home/airflow/.local/lib/python3.7/site-packages/airflow/operators/python.py", line 175, in execute
    return_value = self.execute_callable()
  File "/home/airflow/.local/lib/python3.7/site-packages/airflow/operators/python.py", line 192, in execute_callable
    return self.python_callable(*self.op_args, **self.op_kwargs)
  File "/opt/airflow/dags/process_data.py", line 135, in fetch_and_save_data
    formatted_weather_data = format_data(weather_data)
  File "/opt/airflow/dags/process_data.py", line 51, in format_data
    formatted_data = {"City": data["city"]["name"], "Country": data["city"]["country"], "Forecast": []}
KeyError: 'city'
[2024-06-16T14:00:54.608+0000] {taskinstance.py:1323} INFO - Marking task as UP_FOR_RETRY. dag_id=process_data_dag, task_id=fetch_and_save_data, execution_date=20240616T135918, start_date=20240616T135929, end_date=20240616T140054
[2024-06-16T14:00:54.617+0000] {standard_task_runner.py:105} ERROR - Failed to execute job 33237 for task fetch_and_save_data ('city'; 1049)
[2024-06-16T14:00:54.651+0000] {local_task_job.py:208} INFO - Task exited with return code 1
[2024-06-16T14:00:54.669+0000] {taskinstance.py:2578} INFO - 0 downstream tasks scheduled from follow-on schedule check
