[2024-06-16T01:48:03.546+0000] {taskinstance.py:1083} INFO - Dependencies all met for <TaskInstance: process_data_dag.fetch_and_save_data scheduled__2023-01-01T00:00:00+00:00 [queued]>
[2024-06-16T01:48:03.555+0000] {taskinstance.py:1083} INFO - Dependencies all met for <TaskInstance: process_data_dag.fetch_and_save_data scheduled__2023-01-01T00:00:00+00:00 [queued]>
[2024-06-16T01:48:03.555+0000] {taskinstance.py:1279} INFO - 
--------------------------------------------------------------------------------
[2024-06-16T01:48:03.556+0000] {taskinstance.py:1280} INFO - Starting attempt 1 of 2
[2024-06-16T01:48:03.556+0000] {taskinstance.py:1281} INFO - 
--------------------------------------------------------------------------------
[2024-06-16T01:48:03.640+0000] {taskinstance.py:1300} INFO - Executing <Task(PythonOperator): fetch_and_save_data> on 2023-01-01 00:00:00+00:00
[2024-06-16T01:48:03.652+0000] {standard_task_runner.py:55} INFO - Started process 240 to run task
[2024-06-16T01:48:03.656+0000] {standard_task_runner.py:82} INFO - Running: ['***', 'tasks', 'run', 'process_data_dag', 'fetch_and_save_data', 'scheduled__2023-01-01T00:00:00+00:00', '--job-id', '32056', '--raw', '--subdir', 'DAGS_FOLDER/process_data.py', '--cfg-path', '/tmp/tmppacg46z9']
[2024-06-16T01:48:03.656+0000] {standard_task_runner.py:83} INFO - Job 32056: Subtask fetch_and_save_data
[2024-06-16T01:48:03.739+0000] {task_command.py:388} INFO - Running <TaskInstance: process_data_dag.fetch_and_save_data scheduled__2023-01-01T00:00:00+00:00 [running]> on host 74f2b0340b57
[2024-06-16T01:48:03.855+0000] {taskinstance.py:1509} INFO - Exporting the following env vars:
AIRFLOW_CTX_DAG_OWNER=***
AIRFLOW_CTX_DAG_ID=process_data_dag
AIRFLOW_CTX_TASK_ID=fetch_and_save_data
AIRFLOW_CTX_EXECUTION_DATE=2023-01-01T00:00:00+00:00
AIRFLOW_CTX_TRY_NUMBER=1
AIRFLOW_CTX_DAG_RUN_ID=scheduled__2023-01-01T00:00:00+00:00
[2024-06-16T01:48:03.857+0000] {taskinstance.py:1768} ERROR - Task failed with exception
Traceback (most recent call last):
  File "/home/airflow/.local/lib/python3.7/site-packages/airflow/operators/python.py", line 175, in execute
    return_value = self.execute_callable()
  File "/home/airflow/.local/lib/python3.7/site-packages/airflow/operators/python.py", line 192, in execute_callable
    return self.python_callable(*self.op_args, **self.op_kwargs)
  File "/opt/airflow/dags/process_data.py", line 34, in fetch_and_save_data
    config = import_config()
  File "/opt/airflow/dags/process_data.py", line 17, in import_config
    with open('/home/evandro/Área de trabalho/case/case_zebrinha-azul/config/config.yaml', 'r') as config:
FileNotFoundError: [Errno 2] No such file or directory: '/home/evandro/Área de trabalho/case/case_zebrinha-azul/config/config.yaml'
[2024-06-16T01:48:03.880+0000] {taskinstance.py:1323} INFO - Marking task as UP_FOR_RETRY. dag_id=process_data_dag, task_id=fetch_and_save_data, execution_date=20230101T000000, start_date=20240616T014803, end_date=20240616T014803
[2024-06-16T01:48:03.899+0000] {standard_task_runner.py:105} ERROR - Failed to execute job 32056 for task fetch_and_save_data ([Errno 2] No such file or directory: '/home/evandro/Área de trabalho/case/case_zebrinha-azul/config/config.yaml'; 240)
[2024-06-16T01:48:03.953+0000] {local_task_job.py:208} INFO - Task exited with return code 1
[2024-06-16T01:48:03.987+0000] {taskinstance.py:2578} INFO - 0 downstream tasks scheduled from follow-on schedule check
[2024-06-16T01:50:17.587+0000] {taskinstance.py:1083} INFO - Dependencies all met for <TaskInstance: process_data_dag.fetch_and_save_data scheduled__2023-01-01T00:00:00+00:00 [queued]>
[2024-06-16T01:50:17.595+0000] {taskinstance.py:1083} INFO - Dependencies all met for <TaskInstance: process_data_dag.fetch_and_save_data scheduled__2023-01-01T00:00:00+00:00 [queued]>
[2024-06-16T01:50:17.595+0000] {taskinstance.py:1279} INFO - 
--------------------------------------------------------------------------------
[2024-06-16T01:50:17.595+0000] {taskinstance.py:1280} INFO - Starting attempt 1 of 2
[2024-06-16T01:50:17.595+0000] {taskinstance.py:1281} INFO - 
--------------------------------------------------------------------------------
[2024-06-16T01:50:17.625+0000] {taskinstance.py:1300} INFO - Executing <Task(PythonOperator): fetch_and_save_data> on 2023-01-01 00:00:00+00:00
[2024-06-16T01:50:17.633+0000] {standard_task_runner.py:55} INFO - Started process 590 to run task
[2024-06-16T01:50:17.636+0000] {standard_task_runner.py:82} INFO - Running: ['***', 'tasks', 'run', 'process_data_dag', 'fetch_and_save_data', 'scheduled__2023-01-01T00:00:00+00:00', '--job-id', '32079', '--raw', '--subdir', 'DAGS_FOLDER/process_data.py', '--cfg-path', '/tmp/tmpd266ii7j']
[2024-06-16T01:50:17.636+0000] {standard_task_runner.py:83} INFO - Job 32079: Subtask fetch_and_save_data
[2024-06-16T01:50:17.698+0000] {task_command.py:388} INFO - Running <TaskInstance: process_data_dag.fetch_and_save_data scheduled__2023-01-01T00:00:00+00:00 [running]> on host 74f2b0340b57
[2024-06-16T01:50:17.776+0000] {taskinstance.py:1509} INFO - Exporting the following env vars:
AIRFLOW_CTX_DAG_OWNER=***
AIRFLOW_CTX_DAG_ID=process_data_dag
AIRFLOW_CTX_TASK_ID=fetch_and_save_data
AIRFLOW_CTX_EXECUTION_DATE=2023-01-01T00:00:00+00:00
AIRFLOW_CTX_TRY_NUMBER=1
AIRFLOW_CTX_DAG_RUN_ID=scheduled__2023-01-01T00:00:00+00:00
[2024-06-16T01:50:17.778+0000] {taskinstance.py:1768} ERROR - Task failed with exception
Traceback (most recent call last):
  File "/home/airflow/.local/lib/python3.7/site-packages/airflow/operators/python.py", line 175, in execute
    return_value = self.execute_callable()
  File "/home/airflow/.local/lib/python3.7/site-packages/airflow/operators/python.py", line 192, in execute_callable
    return self.python_callable(*self.op_args, **self.op_kwargs)
  File "/opt/airflow/dags/process_data.py", line 34, in fetch_and_save_data
    config = import_config()
  File "/opt/airflow/dags/process_data.py", line 17, in import_config
    with open('home/evandro/Área de trabalho/case/case_zebrinha-azul/config/config.yaml', 'r') as config:
FileNotFoundError: [Errno 2] No such file or directory: 'home/evandro/Área de trabalho/case/case_zebrinha-azul/config/config.yaml'
[2024-06-16T01:50:17.787+0000] {taskinstance.py:1323} INFO - Marking task as UP_FOR_RETRY. dag_id=process_data_dag, task_id=fetch_and_save_data, execution_date=20230101T000000, start_date=20240616T015017, end_date=20240616T015017
[2024-06-16T01:50:17.799+0000] {standard_task_runner.py:105} ERROR - Failed to execute job 32079 for task fetch_and_save_data ([Errno 2] No such file or directory: 'home/evandro/Área de trabalho/case/case_zebrinha-azul/config/config.yaml'; 590)
[2024-06-16T01:50:17.847+0000] {local_task_job.py:208} INFO - Task exited with return code 1
[2024-06-16T01:50:17.878+0000] {taskinstance.py:2578} INFO - 0 downstream tasks scheduled from follow-on schedule check
[2024-06-16T01:52:26.714+0000] {taskinstance.py:1083} INFO - Dependencies all met for <TaskInstance: process_data_dag.fetch_and_save_data scheduled__2023-01-01T00:00:00+00:00 [queued]>
[2024-06-16T01:52:26.722+0000] {taskinstance.py:1083} INFO - Dependencies all met for <TaskInstance: process_data_dag.fetch_and_save_data scheduled__2023-01-01T00:00:00+00:00 [queued]>
[2024-06-16T01:52:26.722+0000] {taskinstance.py:1279} INFO - 
--------------------------------------------------------------------------------
[2024-06-16T01:52:26.723+0000] {taskinstance.py:1280} INFO - Starting attempt 1 of 2
[2024-06-16T01:52:26.723+0000] {taskinstance.py:1281} INFO - 
--------------------------------------------------------------------------------
[2024-06-16T01:52:26.736+0000] {taskinstance.py:1300} INFO - Executing <Task(PythonOperator): fetch_and_save_data> on 2023-01-01 00:00:00+00:00
[2024-06-16T01:52:26.744+0000] {standard_task_runner.py:55} INFO - Started process 927 to run task
[2024-06-16T01:52:26.747+0000] {standard_task_runner.py:82} INFO - Running: ['***', 'tasks', 'run', 'process_data_dag', 'fetch_and_save_data', 'scheduled__2023-01-01T00:00:00+00:00', '--job-id', '32106', '--raw', '--subdir', 'DAGS_FOLDER/process_data.py', '--cfg-path', '/tmp/tmp05er1f40']
[2024-06-16T01:52:26.747+0000] {standard_task_runner.py:83} INFO - Job 32106: Subtask fetch_and_save_data
[2024-06-16T01:52:26.805+0000] {task_command.py:388} INFO - Running <TaskInstance: process_data_dag.fetch_and_save_data scheduled__2023-01-01T00:00:00+00:00 [running]> on host 74f2b0340b57
[2024-06-16T01:52:26.894+0000] {taskinstance.py:1509} INFO - Exporting the following env vars:
AIRFLOW_CTX_DAG_OWNER=***
AIRFLOW_CTX_DAG_ID=process_data_dag
AIRFLOW_CTX_TASK_ID=fetch_and_save_data
AIRFLOW_CTX_EXECUTION_DATE=2023-01-01T00:00:00+00:00
AIRFLOW_CTX_TRY_NUMBER=1
AIRFLOW_CTX_DAG_RUN_ID=scheduled__2023-01-01T00:00:00+00:00
[2024-06-16T01:52:26.897+0000] {logging_mixin.py:137} INFO - /opt/***
[2024-06-16T01:52:26.897+0000] {taskinstance.py:1768} ERROR - Task failed with exception
Traceback (most recent call last):
  File "/home/airflow/.local/lib/python3.7/site-packages/airflow/operators/python.py", line 175, in execute
    return_value = self.execute_callable()
  File "/home/airflow/.local/lib/python3.7/site-packages/airflow/operators/python.py", line 192, in execute_callable
    return self.python_callable(*self.op_args, **self.op_kwargs)
  File "/opt/airflow/dags/process_data.py", line 35, in fetch_and_save_data
    config = import_config()
  File "/opt/airflow/dags/process_data.py", line 18, in import_config
    with open('home/evandro/Área de trabalho/case/case_zebrinha-azul/config/config.yaml', 'r') as config:
FileNotFoundError: [Errno 2] No such file or directory: 'home/evandro/Área de trabalho/case/case_zebrinha-azul/config/config.yaml'
[2024-06-16T01:52:26.905+0000] {taskinstance.py:1323} INFO - Marking task as UP_FOR_RETRY. dag_id=process_data_dag, task_id=fetch_and_save_data, execution_date=20230101T000000, start_date=20240616T015226, end_date=20240616T015226
[2024-06-16T01:52:26.919+0000] {standard_task_runner.py:105} ERROR - Failed to execute job 32106 for task fetch_and_save_data ([Errno 2] No such file or directory: 'home/evandro/Área de trabalho/case/case_zebrinha-azul/config/config.yaml'; 927)
[2024-06-16T01:52:26.959+0000] {local_task_job.py:208} INFO - Task exited with return code 1
[2024-06-16T01:52:27.016+0000] {taskinstance.py:2578} INFO - 0 downstream tasks scheduled from follow-on schedule check
[2024-06-16T01:54:48.441+0000] {taskinstance.py:1083} INFO - Dependencies all met for <TaskInstance: process_data_dag.fetch_and_save_data scheduled__2023-01-01T00:00:00+00:00 [queued]>
[2024-06-16T01:54:48.453+0000] {taskinstance.py:1083} INFO - Dependencies all met for <TaskInstance: process_data_dag.fetch_and_save_data scheduled__2023-01-01T00:00:00+00:00 [queued]>
[2024-06-16T01:54:48.453+0000] {taskinstance.py:1279} INFO - 
--------------------------------------------------------------------------------
[2024-06-16T01:54:48.453+0000] {taskinstance.py:1280} INFO - Starting attempt 1 of 2
[2024-06-16T01:54:48.453+0000] {taskinstance.py:1281} INFO - 
--------------------------------------------------------------------------------
[2024-06-16T01:54:48.474+0000] {taskinstance.py:1300} INFO - Executing <Task(PythonOperator): fetch_and_save_data> on 2023-01-01 00:00:00+00:00
[2024-06-16T01:54:48.485+0000] {standard_task_runner.py:55} INFO - Started process 1307 to run task
[2024-06-16T01:54:48.488+0000] {standard_task_runner.py:82} INFO - Running: ['***', 'tasks', 'run', 'process_data_dag', 'fetch_and_save_data', 'scheduled__2023-01-01T00:00:00+00:00', '--job-id', '32132', '--raw', '--subdir', 'DAGS_FOLDER/process_data.py', '--cfg-path', '/tmp/tmpjbvt400e']
[2024-06-16T01:54:48.489+0000] {standard_task_runner.py:83} INFO - Job 32132: Subtask fetch_and_save_data
[2024-06-16T01:54:48.555+0000] {task_command.py:388} INFO - Running <TaskInstance: process_data_dag.fetch_and_save_data scheduled__2023-01-01T00:00:00+00:00 [running]> on host 74f2b0340b57
[2024-06-16T01:54:48.646+0000] {taskinstance.py:1509} INFO - Exporting the following env vars:
AIRFLOW_CTX_DAG_OWNER=***
AIRFLOW_CTX_DAG_ID=process_data_dag
AIRFLOW_CTX_TASK_ID=fetch_and_save_data
AIRFLOW_CTX_EXECUTION_DATE=2023-01-01T00:00:00+00:00
AIRFLOW_CTX_TRY_NUMBER=1
AIRFLOW_CTX_DAG_RUN_ID=scheduled__2023-01-01T00:00:00+00:00
[2024-06-16T01:54:48.648+0000] {logging_mixin.py:137} INFO - /opt/***
[2024-06-16T01:54:48.648+0000] {taskinstance.py:1768} ERROR - Task failed with exception
Traceback (most recent call last):
  File "/home/airflow/.local/lib/python3.7/site-packages/airflow/operators/python.py", line 175, in execute
    return_value = self.execute_callable()
  File "/home/airflow/.local/lib/python3.7/site-packages/airflow/operators/python.py", line 192, in execute_callable
    return self.python_callable(*self.op_args, **self.op_kwargs)
  File "/opt/airflow/dags/process_data.py", line 35, in fetch_and_save_data
    config = import_config()
  File "/opt/airflow/dags/process_data.py", line 18, in import_config
    with open('config/config.yaml', 'r') as config:
FileNotFoundError: [Errno 2] No such file or directory: 'config/config.yaml'
[2024-06-16T01:54:48.658+0000] {taskinstance.py:1323} INFO - Marking task as UP_FOR_RETRY. dag_id=process_data_dag, task_id=fetch_and_save_data, execution_date=20230101T000000, start_date=20240616T015448, end_date=20240616T015448
[2024-06-16T01:54:48.675+0000] {standard_task_runner.py:105} ERROR - Failed to execute job 32132 for task fetch_and_save_data ([Errno 2] No such file or directory: 'config/config.yaml'; 1307)
[2024-06-16T01:54:48.699+0000] {local_task_job.py:208} INFO - Task exited with return code 1
[2024-06-16T01:54:48.732+0000] {taskinstance.py:2578} INFO - 0 downstream tasks scheduled from follow-on schedule check
