[2024-06-16T03:52:52.997+0000] {taskinstance.py:1083} INFO - Dependencies all met for <TaskInstance: process_data_dag.send_data_to_database manual__2024-06-16T03:41:32.299932+00:00 [failed]>
[2024-06-16T03:52:52.998+0000] {taskinstance.py:1083} INFO - Dependencies all met for <TaskInstance: process_data_dag.send_data_to_database manual__2024-06-16T03:41:32.299932+00:00 [failed]>
[2024-06-16T03:52:52.998+0000] {taskinstance.py:1279} INFO - 
--------------------------------------------------------------------------------
[2024-06-16T03:52:52.998+0000] {taskinstance.py:1280} INFO - Starting attempt 3 of 2
[2024-06-16T03:52:52.998+0000] {taskinstance.py:1281} INFO - 
--------------------------------------------------------------------------------
[2024-06-16T03:52:53.015+0000] {taskinstance.py:1300} INFO - Executing <Task(PythonOperator): send_data_to_database> on 2024-06-16 03:41:32.299932+00:00
[2024-06-16T03:52:53.025+0000] {standard_task_runner.py:55} INFO - Started process 1875 to run task
[2024-06-16T03:52:53.028+0000] {standard_task_runner.py:82} INFO - Running: ['***', 'tasks', 'run', 'process_data_dag', 'send_data_to_database', 'manual__2024-06-16T03:41:32.299932+00:00', '--job-id', '32744', '--pool', 'default_pool', '--raw', '--subdir', 'DAGS_FOLDER/process_data.py', '--cfg-path', '/tmp/tmpe_m7uxoi']
[2024-06-16T03:52:53.028+0000] {standard_task_runner.py:83} INFO - Job 32744: Subtask send_data_to_database
[2024-06-16T03:52:53.083+0000] {task_command.py:388} INFO - Running <TaskInstance: process_data_dag.send_data_to_database manual__2024-06-16T03:41:32.299932+00:00 [running]> on host 1caec24182a1
[2024-06-16T03:52:53.133+0000] {taskinstance.py:1509} INFO - Exporting the following env vars:
AIRFLOW_CTX_DAG_OWNER=***
AIRFLOW_CTX_DAG_ID=process_data_dag
AIRFLOW_CTX_TASK_ID=send_data_to_database
AIRFLOW_CTX_EXECUTION_DATE=2024-06-16T03:41:32.299932+00:00
AIRFLOW_CTX_TRY_NUMBER=3
AIRFLOW_CTX_DAG_RUN_ID=manual__2024-06-16T03:41:32.299932+00:00
[2024-06-16T03:52:53.152+0000] {taskinstance.py:1768} ERROR - Task failed with exception
Traceback (most recent call last):
  File "/home/airflow/.local/lib/python3.7/site-packages/airflow/operators/python.py", line 175, in execute
    return_value = self.execute_callable()
  File "/home/airflow/.local/lib/python3.7/site-packages/airflow/operators/python.py", line 192, in execute_callable
    return self.python_callable(*self.op_args, **self.op_kwargs)
  File "/opt/airflow/dags/process_data.py", line 169, in send_data_to_database
    connection = create_connection(config)
  File "/opt/airflow/dags/process_data.py", line 29, in create_connection
    engine = create_engine(conn_str)
  File "<string>", line 2, in create_engine
  File "/home/airflow/.local/lib/python3.7/site-packages/sqlalchemy/util/deprecations.py", line 375, in warned
    return fn(*args, **kwargs)
  File "/home/airflow/.local/lib/python3.7/site-packages/sqlalchemy/engine/create.py", line 522, in create_engine
    entrypoint = u._get_entrypoint()
  File "/home/airflow/.local/lib/python3.7/site-packages/sqlalchemy/engine/url.py", line 662, in _get_entrypoint
    cls = registry.load(name)
  File "/home/airflow/.local/lib/python3.7/site-packages/sqlalchemy/util/langhelpers.py", line 344, in load
    "Can't load plugin: %s:%s" % (self.group, name)
sqlalchemy.exc.NoSuchModuleError: Can't load plugin: sqlalchemy.dialects:postgresql.psicopg2
[2024-06-16T03:52:53.159+0000] {taskinstance.py:1323} INFO - Marking task as FAILED. dag_id=process_data_dag, task_id=send_data_to_database, execution_date=20240616T034132, start_date=20240616T035252, end_date=20240616T035253
[2024-06-16T03:52:53.168+0000] {standard_task_runner.py:105} ERROR - Failed to execute job 32744 for task send_data_to_database (Can't load plugin: sqlalchemy.dialects:postgresql.psicopg2; 1875)
[2024-06-16T03:52:53.199+0000] {local_task_job.py:208} INFO - Task exited with return code 1
[2024-06-16T03:52:53.222+0000] {taskinstance.py:2578} INFO - 0 downstream tasks scheduled from follow-on schedule check
