[2024-06-16T01:48:03.921+0000] {taskinstance.py:1083} INFO - Dependencies all met for <TaskInstance: process_data_dag.fetch_and_save_data scheduled__2023-01-05T00:00:00+00:00 [queued]>
[2024-06-16T01:48:03.931+0000] {taskinstance.py:1083} INFO - Dependencies all met for <TaskInstance: process_data_dag.fetch_and_save_data scheduled__2023-01-05T00:00:00+00:00 [queued]>
[2024-06-16T01:48:03.932+0000] {taskinstance.py:1279} INFO - 
--------------------------------------------------------------------------------
[2024-06-16T01:48:03.932+0000] {taskinstance.py:1280} INFO - Starting attempt 1 of 2
[2024-06-16T01:48:03.932+0000] {taskinstance.py:1281} INFO - 
--------------------------------------------------------------------------------
[2024-06-16T01:48:03.962+0000] {taskinstance.py:1300} INFO - Executing <Task(PythonOperator): fetch_and_save_data> on 2023-01-05 00:00:00+00:00
[2024-06-16T01:48:03.973+0000] {standard_task_runner.py:55} INFO - Started process 246 to run task
[2024-06-16T01:48:03.976+0000] {standard_task_runner.py:82} INFO - Running: ['***', 'tasks', 'run', 'process_data_dag', 'fetch_and_save_data', 'scheduled__2023-01-05T00:00:00+00:00', '--job-id', '32058', '--raw', '--subdir', 'DAGS_FOLDER/process_data.py', '--cfg-path', '/tmp/tmp5uhlz1cn']
[2024-06-16T01:48:03.977+0000] {standard_task_runner.py:83} INFO - Job 32058: Subtask fetch_and_save_data
[2024-06-16T01:48:04.093+0000] {task_command.py:388} INFO - Running <TaskInstance: process_data_dag.fetch_and_save_data scheduled__2023-01-05T00:00:00+00:00 [running]> on host 74f2b0340b57
[2024-06-16T01:48:04.180+0000] {taskinstance.py:1509} INFO - Exporting the following env vars:
AIRFLOW_CTX_DAG_OWNER=***
AIRFLOW_CTX_DAG_ID=process_data_dag
AIRFLOW_CTX_TASK_ID=fetch_and_save_data
AIRFLOW_CTX_EXECUTION_DATE=2023-01-05T00:00:00+00:00
AIRFLOW_CTX_TRY_NUMBER=1
AIRFLOW_CTX_DAG_RUN_ID=scheduled__2023-01-05T00:00:00+00:00
[2024-06-16T01:48:04.182+0000] {taskinstance.py:1768} ERROR - Task failed with exception
Traceback (most recent call last):
  File "/home/airflow/.local/lib/python3.7/site-packages/airflow/operators/python.py", line 175, in execute
    return_value = self.execute_callable()
  File "/home/airflow/.local/lib/python3.7/site-packages/airflow/operators/python.py", line 192, in execute_callable
    return self.python_callable(*self.op_args, **self.op_kwargs)
  File "/opt/airflow/dags/process_data.py", line 34, in fetch_and_save_data
    config = import_config()
  File "/opt/airflow/dags/process_data.py", line 17, in import_config
    with open('/home/evandro/Área de trabalho/case/case_zebrinha-azul/config/config.yaml', 'r') as config:
FileNotFoundError: [Errno 2] No such file or directory: '/home/evandro/Área de trabalho/case/case_zebrinha-azul/config/config.yaml'
[2024-06-16T01:48:04.190+0000] {taskinstance.py:1323} INFO - Marking task as UP_FOR_RETRY. dag_id=process_data_dag, task_id=fetch_and_save_data, execution_date=20230105T000000, start_date=20240616T014803, end_date=20240616T014804
[2024-06-16T01:48:04.203+0000] {standard_task_runner.py:105} ERROR - Failed to execute job 32058 for task fetch_and_save_data ([Errno 2] No such file or directory: '/home/evandro/Área de trabalho/case/case_zebrinha-azul/config/config.yaml'; 246)
[2024-06-16T01:48:04.235+0000] {local_task_job.py:208} INFO - Task exited with return code 1
[2024-06-16T01:48:04.266+0000] {taskinstance.py:2578} INFO - 0 downstream tasks scheduled from follow-on schedule check
[2024-06-16T01:50:18.165+0000] {taskinstance.py:1083} INFO - Dependencies all met for <TaskInstance: process_data_dag.fetch_and_save_data scheduled__2023-01-05T00:00:00+00:00 [queued]>
[2024-06-16T01:50:18.175+0000] {taskinstance.py:1083} INFO - Dependencies all met for <TaskInstance: process_data_dag.fetch_and_save_data scheduled__2023-01-05T00:00:00+00:00 [queued]>
[2024-06-16T01:50:18.175+0000] {taskinstance.py:1279} INFO - 
--------------------------------------------------------------------------------
[2024-06-16T01:50:18.175+0000] {taskinstance.py:1280} INFO - Starting attempt 1 of 2
[2024-06-16T01:50:18.175+0000] {taskinstance.py:1281} INFO - 
--------------------------------------------------------------------------------
[2024-06-16T01:50:18.233+0000] {taskinstance.py:1300} INFO - Executing <Task(PythonOperator): fetch_and_save_data> on 2023-01-05 00:00:00+00:00
[2024-06-16T01:50:18.242+0000] {standard_task_runner.py:55} INFO - Started process 601 to run task
[2024-06-16T01:50:18.244+0000] {standard_task_runner.py:82} INFO - Running: ['***', 'tasks', 'run', 'process_data_dag', 'fetch_and_save_data', 'scheduled__2023-01-05T00:00:00+00:00', '--job-id', '32084', '--raw', '--subdir', 'DAGS_FOLDER/process_data.py', '--cfg-path', '/tmp/tmplynojanh']
[2024-06-16T01:50:18.245+0000] {standard_task_runner.py:83} INFO - Job 32084: Subtask fetch_and_save_data
[2024-06-16T01:50:18.300+0000] {task_command.py:388} INFO - Running <TaskInstance: process_data_dag.fetch_and_save_data scheduled__2023-01-05T00:00:00+00:00 [running]> on host 74f2b0340b57
[2024-06-16T01:50:18.368+0000] {taskinstance.py:1509} INFO - Exporting the following env vars:
AIRFLOW_CTX_DAG_OWNER=***
AIRFLOW_CTX_DAG_ID=process_data_dag
AIRFLOW_CTX_TASK_ID=fetch_and_save_data
AIRFLOW_CTX_EXECUTION_DATE=2023-01-05T00:00:00+00:00
AIRFLOW_CTX_TRY_NUMBER=1
AIRFLOW_CTX_DAG_RUN_ID=scheduled__2023-01-05T00:00:00+00:00
[2024-06-16T01:50:18.370+0000] {taskinstance.py:1768} ERROR - Task failed with exception
Traceback (most recent call last):
  File "/home/airflow/.local/lib/python3.7/site-packages/airflow/operators/python.py", line 175, in execute
    return_value = self.execute_callable()
  File "/home/airflow/.local/lib/python3.7/site-packages/airflow/operators/python.py", line 192, in execute_callable
    return self.python_callable(*self.op_args, **self.op_kwargs)
  File "/opt/airflow/dags/process_data.py", line 34, in fetch_and_save_data
    config = import_config()
  File "/opt/airflow/dags/process_data.py", line 17, in import_config
    with open('home/evandro/Área de trabalho/case/case_zebrinha-azul/config/config.yaml', 'r') as config:
FileNotFoundError: [Errno 2] No such file or directory: 'home/evandro/Área de trabalho/case/case_zebrinha-azul/config/config.yaml'
[2024-06-16T01:50:18.378+0000] {taskinstance.py:1323} INFO - Marking task as UP_FOR_RETRY. dag_id=process_data_dag, task_id=fetch_and_save_data, execution_date=20230105T000000, start_date=20240616T015018, end_date=20240616T015018
[2024-06-16T01:50:18.388+0000] {standard_task_runner.py:105} ERROR - Failed to execute job 32084 for task fetch_and_save_data ([Errno 2] No such file or directory: 'home/evandro/Área de trabalho/case/case_zebrinha-azul/config/config.yaml'; 601)
[2024-06-16T01:50:18.416+0000] {local_task_job.py:208} INFO - Task exited with return code 1
[2024-06-16T01:50:18.450+0000] {taskinstance.py:2578} INFO - 0 downstream tasks scheduled from follow-on schedule check
[2024-06-16T01:52:27.350+0000] {taskinstance.py:1083} INFO - Dependencies all met for <TaskInstance: process_data_dag.fetch_and_save_data scheduled__2023-01-05T00:00:00+00:00 [queued]>
[2024-06-16T01:52:27.357+0000] {taskinstance.py:1083} INFO - Dependencies all met for <TaskInstance: process_data_dag.fetch_and_save_data scheduled__2023-01-05T00:00:00+00:00 [queued]>
[2024-06-16T01:52:27.357+0000] {taskinstance.py:1279} INFO - 
--------------------------------------------------------------------------------
[2024-06-16T01:52:27.357+0000] {taskinstance.py:1280} INFO - Starting attempt 1 of 2
[2024-06-16T01:52:27.358+0000] {taskinstance.py:1281} INFO - 
--------------------------------------------------------------------------------
[2024-06-16T01:52:27.414+0000] {taskinstance.py:1300} INFO - Executing <Task(PythonOperator): fetch_and_save_data> on 2023-01-05 00:00:00+00:00
[2024-06-16T01:52:27.424+0000] {standard_task_runner.py:55} INFO - Started process 938 to run task
[2024-06-16T01:52:27.428+0000] {standard_task_runner.py:82} INFO - Running: ['***', 'tasks', 'run', 'process_data_dag', 'fetch_and_save_data', 'scheduled__2023-01-05T00:00:00+00:00', '--job-id', '32111', '--raw', '--subdir', 'DAGS_FOLDER/process_data.py', '--cfg-path', '/tmp/tmpn58q_rdx']
[2024-06-16T01:52:27.428+0000] {standard_task_runner.py:83} INFO - Job 32111: Subtask fetch_and_save_data
[2024-06-16T01:52:27.499+0000] {task_command.py:388} INFO - Running <TaskInstance: process_data_dag.fetch_and_save_data scheduled__2023-01-05T00:00:00+00:00 [running]> on host 74f2b0340b57
[2024-06-16T01:52:27.584+0000] {taskinstance.py:1509} INFO - Exporting the following env vars:
AIRFLOW_CTX_DAG_OWNER=***
AIRFLOW_CTX_DAG_ID=process_data_dag
AIRFLOW_CTX_TASK_ID=fetch_and_save_data
AIRFLOW_CTX_EXECUTION_DATE=2023-01-05T00:00:00+00:00
AIRFLOW_CTX_TRY_NUMBER=1
AIRFLOW_CTX_DAG_RUN_ID=scheduled__2023-01-05T00:00:00+00:00
[2024-06-16T01:52:27.586+0000] {logging_mixin.py:137} INFO - /opt/***
[2024-06-16T01:52:27.586+0000] {taskinstance.py:1768} ERROR - Task failed with exception
Traceback (most recent call last):
  File "/home/airflow/.local/lib/python3.7/site-packages/airflow/operators/python.py", line 175, in execute
    return_value = self.execute_callable()
  File "/home/airflow/.local/lib/python3.7/site-packages/airflow/operators/python.py", line 192, in execute_callable
    return self.python_callable(*self.op_args, **self.op_kwargs)
  File "/opt/airflow/dags/process_data.py", line 35, in fetch_and_save_data
    config = import_config()
  File "/opt/airflow/dags/process_data.py", line 18, in import_config
    with open('home/evandro/Área de trabalho/case/case_zebrinha-azul/config/config.yaml', 'r') as config:
FileNotFoundError: [Errno 2] No such file or directory: 'home/evandro/Área de trabalho/case/case_zebrinha-azul/config/config.yaml'
[2024-06-16T01:52:27.594+0000] {taskinstance.py:1323} INFO - Marking task as UP_FOR_RETRY. dag_id=process_data_dag, task_id=fetch_and_save_data, execution_date=20230105T000000, start_date=20240616T015227, end_date=20240616T015227
[2024-06-16T01:52:27.606+0000] {standard_task_runner.py:105} ERROR - Failed to execute job 32111 for task fetch_and_save_data ([Errno 2] No such file or directory: 'home/evandro/Área de trabalho/case/case_zebrinha-azul/config/config.yaml'; 938)
[2024-06-16T01:52:27.639+0000] {local_task_job.py:208} INFO - Task exited with return code 1
[2024-06-16T01:52:27.667+0000] {taskinstance.py:2578} INFO - 0 downstream tasks scheduled from follow-on schedule check
[2024-06-16T01:54:49.121+0000] {taskinstance.py:1083} INFO - Dependencies all met for <TaskInstance: process_data_dag.fetch_and_save_data scheduled__2023-01-05T00:00:00+00:00 [queued]>
[2024-06-16T01:54:49.130+0000] {taskinstance.py:1083} INFO - Dependencies all met for <TaskInstance: process_data_dag.fetch_and_save_data scheduled__2023-01-05T00:00:00+00:00 [queued]>
[2024-06-16T01:54:49.131+0000] {taskinstance.py:1279} INFO - 
--------------------------------------------------------------------------------
[2024-06-16T01:54:49.131+0000] {taskinstance.py:1280} INFO - Starting attempt 1 of 2
[2024-06-16T01:54:49.131+0000] {taskinstance.py:1281} INFO - 
--------------------------------------------------------------------------------
[2024-06-16T01:54:49.249+0000] {taskinstance.py:1300} INFO - Executing <Task(PythonOperator): fetch_and_save_data> on 2023-01-05 00:00:00+00:00
[2024-06-16T01:54:49.260+0000] {standard_task_runner.py:55} INFO - Started process 1318 to run task
[2024-06-16T01:54:49.262+0000] {standard_task_runner.py:82} INFO - Running: ['***', 'tasks', 'run', 'process_data_dag', 'fetch_and_save_data', 'scheduled__2023-01-05T00:00:00+00:00', '--job-id', '32137', '--raw', '--subdir', 'DAGS_FOLDER/process_data.py', '--cfg-path', '/tmp/tmp671dtowq']
[2024-06-16T01:54:49.263+0000] {standard_task_runner.py:83} INFO - Job 32137: Subtask fetch_and_save_data
[2024-06-16T01:54:49.330+0000] {task_command.py:388} INFO - Running <TaskInstance: process_data_dag.fetch_and_save_data scheduled__2023-01-05T00:00:00+00:00 [running]> on host 74f2b0340b57
[2024-06-16T01:54:49.408+0000] {taskinstance.py:1509} INFO - Exporting the following env vars:
AIRFLOW_CTX_DAG_OWNER=***
AIRFLOW_CTX_DAG_ID=process_data_dag
AIRFLOW_CTX_TASK_ID=fetch_and_save_data
AIRFLOW_CTX_EXECUTION_DATE=2023-01-05T00:00:00+00:00
AIRFLOW_CTX_TRY_NUMBER=1
AIRFLOW_CTX_DAG_RUN_ID=scheduled__2023-01-05T00:00:00+00:00
[2024-06-16T01:54:49.410+0000] {logging_mixin.py:137} INFO - /opt/***
[2024-06-16T01:54:49.410+0000] {taskinstance.py:1768} ERROR - Task failed with exception
Traceback (most recent call last):
  File "/home/airflow/.local/lib/python3.7/site-packages/airflow/operators/python.py", line 175, in execute
    return_value = self.execute_callable()
  File "/home/airflow/.local/lib/python3.7/site-packages/airflow/operators/python.py", line 192, in execute_callable
    return self.python_callable(*self.op_args, **self.op_kwargs)
  File "/opt/airflow/dags/process_data.py", line 35, in fetch_and_save_data
    config = import_config()
  File "/opt/airflow/dags/process_data.py", line 18, in import_config
    with open('config/config.yaml', 'r') as config:
FileNotFoundError: [Errno 2] No such file or directory: 'config/config.yaml'
[2024-06-16T01:54:49.417+0000] {taskinstance.py:1323} INFO - Marking task as UP_FOR_RETRY. dag_id=process_data_dag, task_id=fetch_and_save_data, execution_date=20230105T000000, start_date=20240616T015449, end_date=20240616T015449
[2024-06-16T01:54:49.430+0000] {standard_task_runner.py:105} ERROR - Failed to execute job 32137 for task fetch_and_save_data ([Errno 2] No such file or directory: 'config/config.yaml'; 1318)
[2024-06-16T01:54:49.474+0000] {local_task_job.py:208} INFO - Task exited with return code 1
[2024-06-16T01:54:49.506+0000] {taskinstance.py:2578} INFO - 0 downstream tasks scheduled from follow-on schedule check
