[2024-06-16T01:48:03.515+0000] {taskinstance.py:1083} INFO - Dependencies all met for <TaskInstance: process_data_dag.fetch_and_save_data scheduled__2023-01-03T00:00:00+00:00 [queued]>
[2024-06-16T01:48:03.527+0000] {taskinstance.py:1083} INFO - Dependencies all met for <TaskInstance: process_data_dag.fetch_and_save_data scheduled__2023-01-03T00:00:00+00:00 [queued]>
[2024-06-16T01:48:03.527+0000] {taskinstance.py:1279} INFO - 
--------------------------------------------------------------------------------
[2024-06-16T01:48:03.528+0000] {taskinstance.py:1280} INFO - Starting attempt 1 of 2
[2024-06-16T01:48:03.528+0000] {taskinstance.py:1281} INFO - 
--------------------------------------------------------------------------------
[2024-06-16T01:48:03.638+0000] {taskinstance.py:1300} INFO - Executing <Task(PythonOperator): fetch_and_save_data> on 2023-01-03 00:00:00+00:00
[2024-06-16T01:48:03.650+0000] {standard_task_runner.py:55} INFO - Started process 239 to run task
[2024-06-16T01:48:03.653+0000] {standard_task_runner.py:82} INFO - Running: ['***', 'tasks', 'run', 'process_data_dag', 'fetch_and_save_data', 'scheduled__2023-01-03T00:00:00+00:00', '--job-id', '32053', '--raw', '--subdir', 'DAGS_FOLDER/process_data.py', '--cfg-path', '/tmp/tmp9qgz9eay']
[2024-06-16T01:48:03.654+0000] {standard_task_runner.py:83} INFO - Job 32053: Subtask fetch_and_save_data
[2024-06-16T01:48:03.738+0000] {task_command.py:388} INFO - Running <TaskInstance: process_data_dag.fetch_and_save_data scheduled__2023-01-03T00:00:00+00:00 [running]> on host 74f2b0340b57
[2024-06-16T01:48:03.845+0000] {taskinstance.py:1509} INFO - Exporting the following env vars:
AIRFLOW_CTX_DAG_OWNER=***
AIRFLOW_CTX_DAG_ID=process_data_dag
AIRFLOW_CTX_TASK_ID=fetch_and_save_data
AIRFLOW_CTX_EXECUTION_DATE=2023-01-03T00:00:00+00:00
AIRFLOW_CTX_TRY_NUMBER=1
AIRFLOW_CTX_DAG_RUN_ID=scheduled__2023-01-03T00:00:00+00:00
[2024-06-16T01:48:03.852+0000] {taskinstance.py:1768} ERROR - Task failed with exception
Traceback (most recent call last):
  File "/home/airflow/.local/lib/python3.7/site-packages/airflow/operators/python.py", line 175, in execute
    return_value = self.execute_callable()
  File "/home/airflow/.local/lib/python3.7/site-packages/airflow/operators/python.py", line 192, in execute_callable
    return self.python_callable(*self.op_args, **self.op_kwargs)
  File "/opt/airflow/dags/process_data.py", line 34, in fetch_and_save_data
    config = import_config()
  File "/opt/airflow/dags/process_data.py", line 17, in import_config
    with open('/home/evandro/Área de trabalho/case/case_zebrinha-azul/config/config.yaml', 'r') as config:
FileNotFoundError: [Errno 2] No such file or directory: '/home/evandro/Área de trabalho/case/case_zebrinha-azul/config/config.yaml'
[2024-06-16T01:48:03.864+0000] {taskinstance.py:1323} INFO - Marking task as UP_FOR_RETRY. dag_id=process_data_dag, task_id=fetch_and_save_data, execution_date=20230103T000000, start_date=20240616T014803, end_date=20240616T014803
[2024-06-16T01:48:03.887+0000] {standard_task_runner.py:105} ERROR - Failed to execute job 32053 for task fetch_and_save_data ([Errno 2] No such file or directory: '/home/evandro/Área de trabalho/case/case_zebrinha-azul/config/config.yaml'; 239)
[2024-06-16T01:48:03.910+0000] {local_task_job.py:208} INFO - Task exited with return code 1
[2024-06-16T01:48:03.940+0000] {taskinstance.py:2578} INFO - 0 downstream tasks scheduled from follow-on schedule check
[2024-06-16T01:50:17.852+0000] {taskinstance.py:1083} INFO - Dependencies all met for <TaskInstance: process_data_dag.fetch_and_save_data scheduled__2023-01-03T00:00:00+00:00 [queued]>
[2024-06-16T01:50:17.862+0000] {taskinstance.py:1083} INFO - Dependencies all met for <TaskInstance: process_data_dag.fetch_and_save_data scheduled__2023-01-03T00:00:00+00:00 [queued]>
[2024-06-16T01:50:17.862+0000] {taskinstance.py:1279} INFO - 
--------------------------------------------------------------------------------
[2024-06-16T01:50:17.862+0000] {taskinstance.py:1280} INFO - Starting attempt 1 of 2
[2024-06-16T01:50:17.862+0000] {taskinstance.py:1281} INFO - 
--------------------------------------------------------------------------------
[2024-06-16T01:50:17.878+0000] {taskinstance.py:1300} INFO - Executing <Task(PythonOperator): fetch_and_save_data> on 2023-01-03 00:00:00+00:00
[2024-06-16T01:50:17.888+0000] {standard_task_runner.py:55} INFO - Started process 596 to run task
[2024-06-16T01:50:17.891+0000] {standard_task_runner.py:82} INFO - Running: ['***', 'tasks', 'run', 'process_data_dag', 'fetch_and_save_data', 'scheduled__2023-01-03T00:00:00+00:00', '--job-id', '32082', '--raw', '--subdir', 'DAGS_FOLDER/process_data.py', '--cfg-path', '/tmp/tmp4j2z7st7']
[2024-06-16T01:50:17.891+0000] {standard_task_runner.py:83} INFO - Job 32082: Subtask fetch_and_save_data
[2024-06-16T01:50:17.956+0000] {task_command.py:388} INFO - Running <TaskInstance: process_data_dag.fetch_and_save_data scheduled__2023-01-03T00:00:00+00:00 [running]> on host 74f2b0340b57
[2024-06-16T01:50:18.028+0000] {taskinstance.py:1509} INFO - Exporting the following env vars:
AIRFLOW_CTX_DAG_OWNER=***
AIRFLOW_CTX_DAG_ID=process_data_dag
AIRFLOW_CTX_TASK_ID=fetch_and_save_data
AIRFLOW_CTX_EXECUTION_DATE=2023-01-03T00:00:00+00:00
AIRFLOW_CTX_TRY_NUMBER=1
AIRFLOW_CTX_DAG_RUN_ID=scheduled__2023-01-03T00:00:00+00:00
[2024-06-16T01:50:18.030+0000] {taskinstance.py:1768} ERROR - Task failed with exception
Traceback (most recent call last):
  File "/home/airflow/.local/lib/python3.7/site-packages/airflow/operators/python.py", line 175, in execute
    return_value = self.execute_callable()
  File "/home/airflow/.local/lib/python3.7/site-packages/airflow/operators/python.py", line 192, in execute_callable
    return self.python_callable(*self.op_args, **self.op_kwargs)
  File "/opt/airflow/dags/process_data.py", line 34, in fetch_and_save_data
    config = import_config()
  File "/opt/airflow/dags/process_data.py", line 17, in import_config
    with open('home/evandro/Área de trabalho/case/case_zebrinha-azul/config/config.yaml', 'r') as config:
FileNotFoundError: [Errno 2] No such file or directory: 'home/evandro/Área de trabalho/case/case_zebrinha-azul/config/config.yaml'
[2024-06-16T01:50:18.037+0000] {taskinstance.py:1323} INFO - Marking task as UP_FOR_RETRY. dag_id=process_data_dag, task_id=fetch_and_save_data, execution_date=20230103T000000, start_date=20240616T015017, end_date=20240616T015018
[2024-06-16T01:50:18.048+0000] {standard_task_runner.py:105} ERROR - Failed to execute job 32082 for task fetch_and_save_data ([Errno 2] No such file or directory: 'home/evandro/Área de trabalho/case/case_zebrinha-azul/config/config.yaml'; 596)
[2024-06-16T01:50:18.062+0000] {local_task_job.py:208} INFO - Task exited with return code 1
[2024-06-16T01:50:18.091+0000] {taskinstance.py:2578} INFO - 0 downstream tasks scheduled from follow-on schedule check
[2024-06-16T01:52:26.978+0000] {taskinstance.py:1083} INFO - Dependencies all met for <TaskInstance: process_data_dag.fetch_and_save_data scheduled__2023-01-03T00:00:00+00:00 [queued]>
[2024-06-16T01:52:26.985+0000] {taskinstance.py:1083} INFO - Dependencies all met for <TaskInstance: process_data_dag.fetch_and_save_data scheduled__2023-01-03T00:00:00+00:00 [queued]>
[2024-06-16T01:52:26.985+0000] {taskinstance.py:1279} INFO - 
--------------------------------------------------------------------------------
[2024-06-16T01:52:26.985+0000] {taskinstance.py:1280} INFO - Starting attempt 1 of 2
[2024-06-16T01:52:26.985+0000] {taskinstance.py:1281} INFO - 
--------------------------------------------------------------------------------
[2024-06-16T01:52:27.008+0000] {taskinstance.py:1300} INFO - Executing <Task(PythonOperator): fetch_and_save_data> on 2023-01-03 00:00:00+00:00
[2024-06-16T01:52:27.017+0000] {standard_task_runner.py:55} INFO - Started process 931 to run task
[2024-06-16T01:52:27.020+0000] {standard_task_runner.py:82} INFO - Running: ['***', 'tasks', 'run', 'process_data_dag', 'fetch_and_save_data', 'scheduled__2023-01-03T00:00:00+00:00', '--job-id', '32109', '--raw', '--subdir', 'DAGS_FOLDER/process_data.py', '--cfg-path', '/tmp/tmpnh45dte3']
[2024-06-16T01:52:27.021+0000] {standard_task_runner.py:83} INFO - Job 32109: Subtask fetch_and_save_data
[2024-06-16T01:52:27.090+0000] {task_command.py:388} INFO - Running <TaskInstance: process_data_dag.fetch_and_save_data scheduled__2023-01-03T00:00:00+00:00 [running]> on host 74f2b0340b57
[2024-06-16T01:52:27.175+0000] {taskinstance.py:1509} INFO - Exporting the following env vars:
AIRFLOW_CTX_DAG_OWNER=***
AIRFLOW_CTX_DAG_ID=process_data_dag
AIRFLOW_CTX_TASK_ID=fetch_and_save_data
AIRFLOW_CTX_EXECUTION_DATE=2023-01-03T00:00:00+00:00
AIRFLOW_CTX_TRY_NUMBER=1
AIRFLOW_CTX_DAG_RUN_ID=scheduled__2023-01-03T00:00:00+00:00
[2024-06-16T01:52:27.177+0000] {logging_mixin.py:137} INFO - /opt/***
[2024-06-16T01:52:27.177+0000] {taskinstance.py:1768} ERROR - Task failed with exception
Traceback (most recent call last):
  File "/home/airflow/.local/lib/python3.7/site-packages/airflow/operators/python.py", line 175, in execute
    return_value = self.execute_callable()
  File "/home/airflow/.local/lib/python3.7/site-packages/airflow/operators/python.py", line 192, in execute_callable
    return self.python_callable(*self.op_args, **self.op_kwargs)
  File "/opt/airflow/dags/process_data.py", line 35, in fetch_and_save_data
    config = import_config()
  File "/opt/airflow/dags/process_data.py", line 18, in import_config
    with open('home/evandro/Área de trabalho/case/case_zebrinha-azul/config/config.yaml', 'r') as config:
FileNotFoundError: [Errno 2] No such file or directory: 'home/evandro/Área de trabalho/case/case_zebrinha-azul/config/config.yaml'
[2024-06-16T01:52:27.184+0000] {taskinstance.py:1323} INFO - Marking task as UP_FOR_RETRY. dag_id=process_data_dag, task_id=fetch_and_save_data, execution_date=20230103T000000, start_date=20240616T015226, end_date=20240616T015227
[2024-06-16T01:52:27.195+0000] {standard_task_runner.py:105} ERROR - Failed to execute job 32109 for task fetch_and_save_data ([Errno 2] No such file or directory: 'home/evandro/Área de trabalho/case/case_zebrinha-azul/config/config.yaml'; 931)
[2024-06-16T01:52:27.232+0000] {local_task_job.py:208} INFO - Task exited with return code 1
[2024-06-16T01:52:27.262+0000] {taskinstance.py:2578} INFO - 0 downstream tasks scheduled from follow-on schedule check
[2024-06-16T01:54:48.904+0000] {taskinstance.py:1083} INFO - Dependencies all met for <TaskInstance: process_data_dag.fetch_and_save_data scheduled__2023-01-03T00:00:00+00:00 [queued]>
[2024-06-16T01:54:48.916+0000] {taskinstance.py:1083} INFO - Dependencies all met for <TaskInstance: process_data_dag.fetch_and_save_data scheduled__2023-01-03T00:00:00+00:00 [queued]>
[2024-06-16T01:54:48.916+0000] {taskinstance.py:1279} INFO - 
--------------------------------------------------------------------------------
[2024-06-16T01:54:48.916+0000] {taskinstance.py:1280} INFO - Starting attempt 1 of 2
[2024-06-16T01:54:48.916+0000] {taskinstance.py:1281} INFO - 
--------------------------------------------------------------------------------
[2024-06-16T01:54:49.036+0000] {taskinstance.py:1300} INFO - Executing <Task(PythonOperator): fetch_and_save_data> on 2023-01-03 00:00:00+00:00
[2024-06-16T01:54:49.047+0000] {standard_task_runner.py:55} INFO - Started process 1314 to run task
[2024-06-16T01:54:49.049+0000] {standard_task_runner.py:82} INFO - Running: ['***', 'tasks', 'run', 'process_data_dag', 'fetch_and_save_data', 'scheduled__2023-01-03T00:00:00+00:00', '--job-id', '32135', '--raw', '--subdir', 'DAGS_FOLDER/process_data.py', '--cfg-path', '/tmp/tmpbutmvj9d']
[2024-06-16T01:54:49.050+0000] {standard_task_runner.py:83} INFO - Job 32135: Subtask fetch_and_save_data
[2024-06-16T01:54:49.115+0000] {task_command.py:388} INFO - Running <TaskInstance: process_data_dag.fetch_and_save_data scheduled__2023-01-03T00:00:00+00:00 [running]> on host 74f2b0340b57
[2024-06-16T01:54:49.196+0000] {taskinstance.py:1509} INFO - Exporting the following env vars:
AIRFLOW_CTX_DAG_OWNER=***
AIRFLOW_CTX_DAG_ID=process_data_dag
AIRFLOW_CTX_TASK_ID=fetch_and_save_data
AIRFLOW_CTX_EXECUTION_DATE=2023-01-03T00:00:00+00:00
AIRFLOW_CTX_TRY_NUMBER=1
AIRFLOW_CTX_DAG_RUN_ID=scheduled__2023-01-03T00:00:00+00:00
[2024-06-16T01:54:49.198+0000] {logging_mixin.py:137} INFO - /opt/***
[2024-06-16T01:54:49.198+0000] {taskinstance.py:1768} ERROR - Task failed with exception
Traceback (most recent call last):
  File "/home/airflow/.local/lib/python3.7/site-packages/airflow/operators/python.py", line 175, in execute
    return_value = self.execute_callable()
  File "/home/airflow/.local/lib/python3.7/site-packages/airflow/operators/python.py", line 192, in execute_callable
    return self.python_callable(*self.op_args, **self.op_kwargs)
  File "/opt/airflow/dags/process_data.py", line 35, in fetch_and_save_data
    config = import_config()
  File "/opt/airflow/dags/process_data.py", line 18, in import_config
    with open('config/config.yaml', 'r') as config:
FileNotFoundError: [Errno 2] No such file or directory: 'config/config.yaml'
[2024-06-16T01:54:49.206+0000] {taskinstance.py:1323} INFO - Marking task as UP_FOR_RETRY. dag_id=process_data_dag, task_id=fetch_and_save_data, execution_date=20230103T000000, start_date=20240616T015448, end_date=20240616T015449
[2024-06-16T01:54:49.221+0000] {standard_task_runner.py:105} ERROR - Failed to execute job 32135 for task fetch_and_save_data ([Errno 2] No such file or directory: 'config/config.yaml'; 1314)
[2024-06-16T01:54:49.261+0000] {local_task_job.py:208} INFO - Task exited with return code 1
[2024-06-16T01:54:49.293+0000] {taskinstance.py:2578} INFO - 0 downstream tasks scheduled from follow-on schedule check
